<?xml version="1.0" ?>
<robot name="polaris_ranger_xp900">
  <joint name="polaris_ranger_xp900__front_left_steering_joint" type="revolute">
    <parent link="polaris_ranger_xp900__chassis"/>
    <child link="polaris_ranger_xp900__front_left_wheel_steering_block"/>
    <origin rpy="1.57079  0       0" xyz="1.20222  0.5      0.35515"/>
    <axis xyz="0  1  0"/>
    <limit effort="0.0" lower="-0.7727" upper="0.7727" velocity="0.0"/>
  </joint>

  <joint name="polaris_ranger_xp900__front_left_wheel_joint" type="continuous"> 
    <parent link="polaris_ranger_xp900__front_left_wheel_steering_block"/>
    <child link="polaris_ranger_xp900__front_left_wheel"/>
    <origin rpy="-3.09079  0       0" xyz="0      -0.00818 -0.21562"/>
    <axis xyz="0.00000000e+00   8.30000000e-04   1.00000000e+00"/>
    <limit effort="0" lower="0" upper="0" velocity="0"/>
  </joint>
  <joint name="polaris_ranger_xp900__front_right_steering_joint" type="revolute">
    <parent link="polaris_ranger_xp900__chassis"/>
    <child link="polaris_ranger_xp900__front_right_wheel_steering_block"/>
    <origin rpy="1.57079  0       0" xyz="1.20222 -0.5      0.35515"/>
    <axis xyz="0  1  0"/>
    <limit effort="0.0" lower="-0.7727" upper="0.7727" velocity="0.0"/>
  </joint>




  <joint name="polaris_ranger_xp900__front_right_wheel_joint" type="continuous">
    <parent link="polaris_ranger_xp900__front_right_wheel_steering_block"/>
    <child link="polaris_ranger_xp900__front_right_wheel"/>
    <origin rpy="-0.05079  0       0" xyz="0      -0.00818  0.21562"/>
    <axis xyz="0.00000000e+00   8.30000000e-04  -1.00000000e+00"/>
    <limit effort="0" lower="0" upper="0" velocity="0"/>
  </joint>

  <joint name="polaris_ranger_xp900__rear_left_wheel_joint" type="continuous">
    <parent link="polaris_ranger_xp900__chassis"/>
    <child link="polaris_ranger_xp900__rear_left_wheel"/>
    <origin rpy="-1.52  0    0" xyz="-0.99377  0.71562  0.34697"/>
    <axis xyz="0.00000000e+00   8.30000000e-04   1.00000000e+00"/>
    <limit effort="0" lower="0" upper="0" velocity="0"/>
  </joint>

  <joint name="polaris_ranger_xp900__rear_right_wheel_joint" type="continuous">
    <parent link="polaris_ranger_xp900__chassis"/>
    <child link="polaris_ranger_xp900__rear_right_wheel"/>
    <origin rpy="1.52  0    0" xyz="-0.99377 -0.61574  0.34189"/>
    <axis xyz="0.00000000e+00   8.30000000e-04  -1.00000000e+00"/>
    <limit effort="0" lower="0" upper="0" velocity="0"/>
  </joint>








  
  <joint name="polaris_ranger_xp900__gas_joint" type="fixed">
    <parent link="polaris_ranger_xp900__chassis"/>
    <child link="polaris_ranger_xp900__gas_pedal"/>
    <origin rpy="0  0  0" xyz="0.63     0.1      0.57999"/>
    <axis xyz="0.7071  0     -0.7071"/>
    <limit effort="0.0" lower="0.0" upper="0.08" velocity="0.0"/>
  </joint>
  
  <joint name="polaris_ranger_xp900__brake_joint" type="fixed">
    <parent link="polaris_ranger_xp900__chassis"/>
    <child link="polaris_ranger_xp900__brake_pedal"/>
    <origin rpy="0  0  0" xyz="0.64     0.27     0.57999"/>
    <axis xyz="0.85749  0      -0.51449"/>
    <limit effort="0.0" lower="0.0" upper="0.08" velocity="0.0"/>
  </joint>
  
  <joint name="polaris_ranger_xp900__steering_joint" type="fixed">
    <parent link="polaris_ranger_xp900__chassis"/>
    <child link="polaris_ranger_xp900__steering_wheel"/>
    <origin rpy="0   -0.87  0" xyz="0.42  0.46  1.2"/>
    <axis xyz="0  0  1"/>
    <limit effort="0.0" lower="-3.14" upper="3.14" velocity="0.0"/>
  </joint>

  <joint name="polaris_ranger_xp900__hand_brake_joint" type="fixed">
    <parent link="polaris_ranger_xp900__chassis"/>
    <child link="polaris_ranger_xp900__hand_brake"/>
    <origin rpy="0  0  0" xyz="0.53   0.205  1.05"/>
    <axis xyz="0 -1  0"/>
    <limit effort="0.0" lower="0.0" upper="0.6" velocity="0.0"/>
  </joint>

  <joint name="polaris_ranger_xp900__FNR_switch_joint" type="fixed">
    <parent link="polaris_ranger_xp900__chassis"/>
    <child link="polaris_ranger_xp900__FNR_switch"/>
    <origin rpy="0    0.25  0" xyz="0.54     0.1      1.14999"/>
    <axis xyz="0 -1  0"/>
    <limit effort="0.0" lower="-0.3" upper="0.3" velocity="0.0"/>
  </joint>
  <link name="polaris_ranger_xp900__chassis">
    <inertial>
      <mass value="720.0"/>
      <origin rpy="0  0  0" xyz="0.1  0   0.4"/>
      <inertia ixx="140" ixy="0.0" ixz="0.0" iyy="550" iyz="0.0" izz="550"/>
    </inertial>
    <collision name="polaris_ranger_xp900__chassis_bottom">
      <origin rpy="0  0  0" xyz="0.2    0     0.335"/>
      <geometry>
        <box size="1.34 1.65746 0.06"/>
      </geometry>
    </collision>
    <collision name="polaris_ranger_xp900__cargo_bottom">
      <origin rpy="0  0  0" xyz="-1     0     0.921"/>
      <geometry>
        <box size="1.04609 1.6998 0.01"/>
      </geometry>
    </collision>
    <collision name="polaris_ranger_xp900__cargo_front">
      <origin rpy="0  0  0" xyz="-0.495  0     1.06"/>
      <geometry>
        <box size="0.05 1.69982 0.27"/>
      </geometry>
    </collision>
    <collision name="polaris_ranger_xp900__cargo_back">
      <origin rpy="0  0  0" xyz="-1.465  0     1.06"/>
      <geometry>
        <box size="0.05 1.69982 0.27"/>
      </geometry>
    </collision>
    <collision name="polaris_ranger_xp900__cargo_left">
      <origin rpy="0  0  0" xyz="-0.97     0.82491  1.06"/>
      <geometry>
        <box size="1.04609 0.05 0.27"/>
      </geometry>
    </collision>
    <collision name="polaris_ranger_xp900__cargo_right">
      <origin rpy="0  0  0" xyz="-0.97    -0.82491  1.06"/>
      <geometry>
        <box size="1.04609 0.05 0.27"/>
      </geometry>
    </collision>
    <collision name="polaris_ranger_xp900__seat">
      <origin rpy="0  0  0" xyz="0    0    0.62"/>
      <geometry>
        <box size="0.52167 1.37206 0.53369"/>
      </geometry>
    </collision>
    <collision name="polaris_ranger_xp900__mud_seat">
      <origin rpy="0  0  0" xyz="0    0    0.86"/>
      <geometry>
        <box size="0.52167 1.30 0.1"/>
      </geometry>
    </collision>
    <collision name="polaris_ranger_xp900__seat_back">
      <origin rpy="0  -0.2  0" xyz="-0.26   0     1.125"/>
      <geometry>
        <box size="0.06 1.37206 0.6"/>
      </geometry>
    </collision>
    <collision name="polaris_ranger_xp900__engine">
      <origin rpy="0  0  0" xyz="1.12  0    0.7"/>
      <geometry>
        <box size="0.58 1.3 0.8"/>
      </geometry>
    </collision>
    <collision name="polaris_ranger_xp900__central_hump1_collision">
      <origin rpy="0  0  0" xyz="0.55 -0.1   0.4"/>
      <geometry>
        <box size="0.6 0.15 0.1"/>
      </geometry>
    </collision>
    <collision name="polaris_ranger_xp900__central_hump2_collision">
      <origin rpy="0  -0.5  0" xyz="0.7  -0.05  0.45"/>
      <geometry>
        <box size="0.20 0.05 0.1"/>
      </geometry>
    </collision>
    <collision name="polaris_ranger_xp900__central_hump3_collision">
      <origin rpy="0  -0.8  0" xyz="0.798 -0.125  0.478"/>
      <geometry>
        <box size="0.129 0.1 0.05"/>
      </geometry>
    </collision>
    <collision name="polaris_ranger_xp900__central_hump4_collision">
      <origin rpy="0  0  0" xyz="0.8135 -0.05    0.45"/>
      <geometry>
        <box size="0.10 0.05 0.1835"/>
      </geometry>
    </collision>
    <collision name="polaris_ranger_xp900__central_hump5_collision">
      <origin rpy="0  0  0" xyz="0.84  -0.125  0.45"/>
      <geometry>
        <box size="0.03 0.1 0.1835"/>
      </geometry>
    </collision>
    <collision name="polaris_ranger_xp900__central_hump6_collision">
      <origin rpy="0  0  0" xyz="0.82  -0.125  0.475"/>
      <geometry>
        <box size="0.03 0.1 0.05"/>
      </geometry>
    </collision>
    <visual name="polaris_ranger_xp900__visual">
      <origin rpy="0       0      -1.57079" xyz="0  0  0"/>
      <geometry>
        <mesh filename="package://meshes/chasis.dae" scale="1.0 1.0 1.0"/>
      </geometry>
    </visual>
    <visual name="polaris_ranger_xp900__cargo_visual">
      <origin rpy="0      0     -1.5707" xyz="-1      0      1.0323"/>
      <geometry>
        <mesh filename="package://meshes/polaris.dae OR meshes/polaris.dae OR meshes/polaris.dae" scale="1.0 1.0 1.0"/>
      </geometry>
    </visual>
    <visual name="polaris_ranger_xp900__tailgate_visual">
      <origin rpy="0      0     -1.5707" xyz="-1.492  0     1.03"/>
      <geometry>
        <mesh filename="package://meshes/polaris.dae OR meshes/polaris.dae OR meshes/polaris.dae" scale="1.0 1.0 1.0"/>
      </geometry>
    </visual>
    <visual name="polaris_ranger_xp900__front_left_brake_visual">
      <origin rpy="3.1415  0      1.5707" xyz="1.12    -0.57487  0.35516"/>
      <geometry>
        <mesh filename="package://meshes/polaris.dae OR meshes/polaris.dae OR meshes/polaris.dae" scale="1.0 1.0 1.0"/>
      </geometry>
    </visual>
    <visual name="polaris_ranger_xp900__front_right_brake_visual">
      <origin rpy="3.1415  0      1.5707" xyz="1.12     0.57487  0.35516"/>
      <geometry>
        <mesh filename="package://meshes/polaris.dae OR meshes/polaris.dae OR meshes/polaris.dae" scale="1.0 1.0 1.0"/>
      </geometry>
    </visual>
    <visual name="polaris_ranger_xp900__central_hump1">
      <origin rpy="0  0  0" xyz="0.55 -0.1   0.4"/>
      <geometry>
        <box size="0.6 0.15 0.1"/>
      </geometry>
    </visual>
    <visual name="polaris_ranger_xp900__central_hump2">
      <origin rpy="0  -0.5  0" xyz="0.7  -0.05  0.45"/>
      <geometry>
        <box size="0.20 0.05 0.1"/>
      </geometry>
    </visual>
    <visual name="polaris_ranger_xp900__central_hump3">
      <origin rpy="0  -0.8  0" xyz="0.798 -0.125  0.478"/>
      <geometry>
        <box size="0.129 0.1 0.05"/>
      </geometry>
    </visual>
    <visual name="polaris_ranger_xp900__central_hump4">
      <origin rpy="0  0  0" xyz="0.8135 -0.05    0.45"/>
      <geometry>
        <box size="0.10 0.05 0.1835"/>
      </geometry>
    </visual>
    <visual name="polaris_ranger_xp900__central_hump5">
      <origin rpy="0  0  0" xyz="0.84  -0.125  0.45"/>
      <geometry>
        <box size="0.03 0.1 0.1835"/>
      </geometry>
    </visual>
    <visual name="polaris_ranger_xp900__central_hump6">
      <origin rpy="0  0  0" xyz="0.82  -0.125  0.475"/>
      <geometry>
        <box size="0.03 0.1 0.05"/>
      </geometry>
    </visual>
  </link>
  <link name="polaris_ranger_xp900__front_left_wheel">
    <inertial>
      <mass value="12"/>
      <origin rpy="0  0  0" xyz="0  0  0"/>
      <inertia ixx="0.5" ixy="0.0" ixz="0.0" iyy="0.5" iyz="0.0" izz="1.0"/>
    </inertial>
    <collision name="polaris_ranger_xp900__collision">
      <origin rpy="0  0  0" xyz="0  0  0"/>
      <geometry>
        <cylinder length="0.2794" radius="0.3175"/>
      </geometry>
    </collision>
    <visual name="polaris_ranger_xp900__tire_visual">
      <origin rpy="3.14159  1.57079  0" xyz="0  0  0"/>
      <geometry>
        <mesh filename="package://meshes/polaris.dae OR meshes/polaris.dae OR meshes/polaris.dae" scale="1.003700111 0.886200464 0.886200464"/>
      </geometry>
    </visual>
  </link>
  <link name="polaris_ranger_xp900__front_right_wheel">
    <inertial>
      <mass value="12"/>
      <origin rpy="0  0  0" xyz="0  0  0"/>
      <inertia ixx="0.5" ixy="0.0" ixz="0.0" iyy="0.5" iyz="0.0" izz="1.0"/>
    </inertial>
    <collision name="polaris_ranger_xp900__collision">
      <origin rpy="0  0  0" xyz="0  0  0"/>
      <geometry>
        <cylinder length="0.2794" radius="0.3175"/>
      </geometry>
    </collision>
    <visual name="polaris_ranger_xp900__visual">
      <origin rpy="0      -1.57079  0" xyz="0  0  0"/>
      <geometry>
        <mesh filename="package://meshes/polaris.dae OR meshes/polaris.dae OR meshes/polaris.dae" scale="1.003700111 0.886200464 0.886200464"/>
      </geometry>
    </visual>
  </link>
  <link name="polaris_ranger_xp900__rear_left_wheel">
    <inertial>
      <mass value="12"/>
      <origin rpy="0  0  0" xyz="0  0  0"/>
      <inertia ixx="0.5" ixy="0.0" ixz="0.0" iyy="0.5" iyz="0.0" izz="1.0"/>
    </inertial>
    <collision name="polaris_ranger_xp900__collision">
      <origin rpy="0  0  0" xyz="0  0  0"/>
      <geometry>
        <cylinder length="0.2794" radius="0.3175"/>
      </geometry>
    </collision>
    <visual name="polaris_ranger_xp900__visual">
      <origin rpy="0      -1.57079  0" xyz="0  0  0"/>
      <geometry>
        <mesh filename="package://meshes/polaris.dae OR meshes/polaris.dae OR meshes/polaris.dae" scale="1.003700111 0.886200464 0.886200464"/>
      </geometry>
    </visual>
  </link>
  <link name="polaris_ranger_xp900__rear_right_wheel">
    <inertial>
      <mass value="12"/>
      <origin rpy="0  0  0" xyz="0  0  0"/>
      <inertia ixx="0.5" ixy="0.0" ixz="0.0" iyy="0.5" iyz="0.0" izz="1.0"/>
    </inertial>
    <collision name="polaris_ranger_xp900__collision">
      <origin rpy="0  0  0" xyz="0  0  0"/>
      <geometry>
        <cylinder length="0.2794" radius="0.3175"/>
      </geometry>
    </collision>
    <visual name="polaris_ranger_xp900__visual">
      <origin rpy="0      -1.57079  0" xyz="0  0  0"/>
      <geometry>
        <mesh filename="package://meshes/polaris.dae OR meshes/polaris.dae OR meshes/polaris.dae" scale="1.003700111 0.886200464 0.886200464"/>
      </geometry>
    </visual>
  </link>
  <link name="polaris_ranger_xp900__gas_pedal">
    <inertial>
      <mass value="0.1"/>
      <origin rpy="0  0  0" xyz="0  0  0"/>
      <inertia ixx="0.01" ixy="0" ixz="0" iyy="0.01" iyz="0" izz="0.01"/>
    </inertial>
    <collision name="polaris_ranger_xp900__gas_pedal_collision">
      <origin rpy="3.14159  1.12559  3.14159" xyz="-0.0385  0     -0.086"/>
      <geometry>
        <box size="0.1069000 0.0770000 0.010000"/>
      </geometry>
    </collision>
    <visual name="polaris_ranger_xp900__visual">
      <origin rpy="0      0     -1.5707" xyz="0  0  0"/>
      <geometry>
        <mesh filename="package://meshes/polaris.dae OR meshes/polaris.dae OR meshes/polaris.dae" scale="1.0 1.0 1.0"/>
      </geometry>
    </visual>
  </link>
  <link name="polaris_ranger_xp900__brake_pedal">
    <inertial>
      <mass value="0.1"/>
      <origin rpy="0  0  0" xyz="0  0  0"/>
      <inertia ixx="0.01" ixy="0" ixz="0" iyy="0.01" iyz="0" izz="0.01"/>
    </inertial>
    <collision name="polaris_ranger_xp900__brake_pedal_collision">
      <origin rpy="3.14159  1.14259  3.14159" xyz="-0.04   0    -0.086"/>
      <geometry>
        <box size="0.063 0.08 0.01"/>
      </geometry>
    </collision>
    <visual name="polaris_ranger_xp900__visual">
      <origin rpy="0      0     -1.5707" xyz="0  0  0"/>
      <geometry>
        <mesh filename="package://meshes/polaris.dae OR meshes/polaris.dae OR meshes/polaris.dae" scale="1.0 1.0 1.0"/>
      </geometry>
    </visual>
  </link>
  <link name="polaris_ranger_xp900__front_right_wheel_steering_block">
    <inertial>
      <mass value="1"/>
      <origin rpy="0  0  0" xyz="0  0  0"/>
      <inertia ixx="1.0" ixy="0.0" ixz="0.0" iyy="1.0" iyz="0.0" izz="1.0"/>
    </inertial>
    <collision name="polaris_ranger_xp900__collision">
      <origin rpy="0  0  0" xyz="0  0  0"/>
      <geometry>
        <cylinder length="0.01" radius="0.05"/>
      </geometry>
    </collision>
  </link>
  <link name="polaris_ranger_xp900__front_left_wheel_steering_block">
    <inertial>
      <mass value="1"/>
      <origin rpy="0  0  0" xyz="0  0  0"/>
      <inertia ixx="1.0" ixy="0.0" ixz="0.0" iyy="1.0" iyz="0.0" izz="1.0"/>
    </inertial>
    <collision name="polaris_ranger_xp900__collision">
      <origin rpy="0  0  0" xyz="0  0  0"/>
      <geometry>
        <cylinder length="0.01" radius="0.05"/>
      </geometry>
    </collision>
  </link>
  <link name="polaris_ranger_xp900__steering_wheel">
    <inertial>
      <mass value="1.0"/>
      <origin rpy="0  0  0" xyz="-0.002  0     0"/>
      <inertia ixx="0.012" ixy="0" ixz="0" iyy="0.012" iyz="0" izz="0.024"/>
    </inertial>
    <collision name="polaris_ranger_xp900__collision">
      <origin rpy="-0.6108   0      -1.57079" xyz="-0.03     0      -0.12082"/>
      <geometry>
        <mesh filename="package://meshes/polaris.dae OR meshes/polaris.dae OR meshes/polaris.dae" scale="1.0 1.0 1.0"/>
      </geometry>
    </collision>
    <visual name="polaris_ranger_xp900__visual">
      <origin rpy="-0.6108   0      -1.57079" xyz="-0.03     0      -0.12082"/>
      <geometry>
        <mesh filename="package://meshes/polaris.dae OR meshes/polaris.dae OR meshes/polaris.dae" scale="1.0 1.0 1.0"/>
      </geometry>
    </visual>
  </link>
  <link name="polaris_ranger_xp900__hand_brake">
    <inertial>
      <mass value="0.5"/>
      <origin rpy="0  0  0" xyz="0  0  0"/>
      <inertia ixx="0.1" ixy="0" ixz="0" iyy="0.1" iyz="0" izz="0.05"/>
    </inertial>
    <collision name="polaris_ranger_xp900__hand_brake_collision">
      <origin rpy="-0.2      0      -1.57079" xyz="0    0    0.05"/>
      <geometry>
        <mesh filename="package://meshes/polaris.dae OR meshes/polaris.dae OR meshes/polaris.dae" scale="1.0 1.0 1.0"/>
      </geometry>
    </collision>
    <visual name="polaris_ranger_xp900__hand_brake_visual">
      <origin rpy="-0.2      0      -1.57079" xyz="0    0    0.05"/>
      <geometry>
        <mesh filename="package://meshes/polaris.dae OR meshes/polaris.dae OR meshes/polaris.dae" scale="1.0 1.0 1.0"/>
      </geometry>
    </visual>
  </link>
  <link name="polaris_ranger_xp900__FNR_switch">
    <inertial>
      <mass value="0.1"/>
      <origin rpy="0  0  0" xyz="0  0  0"/>
      <inertia ixx="0.1" ixy="0" ixz="0" iyy="0.00006" iyz="0" izz="0.1"/>
    </inertial>
    <collision name="polaris_ranger_xp900__FNR_switch">
      <origin rpy="0  0  0" xyz="0  0  0"/>
      <geometry>
        <box size="0.02 0.04 0.08"/>
      </geometry>
    </collision>
    <visual name="polaris_ranger_xp900__FNR_switch_F">
      <origin rpy="0  0  0" xyz="0  0  0"/>
      <geometry>
        <box size="0.02 0.04 0.08"/>
      </geometry>
    </visual>
    <visual name="polaris_ranger_xp900__FNR_switch_R">
      <origin rpy="0  0  0" xyz="0  0  0"/>
      <geometry>
        <box size="0.0199 0.0399 0.0799"/>
      </geometry>
    </visual>
  </link>
</robot>
